<robot name="dji_e305" xmlns:xacro="http://www.ros.org/wiki/xacro">

  <xacro:macro name="dji_e305" params="number parent direction *origin">

    <xacro:property name="prop_diameter" value="0.24"/>
    <xacro:property name="prop_weight" value="0.013"/>
    <!-- Recommended Max Thrust/RPM: 0.85kg / 800rmp/V 1400 rad/s-->
    <xacro:property name="prop_max_rad_per_sec" value="1400"/>
    <xacro:property name="motor_max_thrust_kgf" value="0.85"/>

    <link name="rotor_${number}">
      <origin xyz="0 0 0" rpy="0 0 0"/>
      <visual>
        <geometry>
          <box size="${prop_diameter} 0.04 0.01"/>
        </geometry>
      </visual>
      <collision>
        <geometry>
          <box size="${prop_diameter} 0.04 0.01"/>
        </geometry>
      </collision>
      <!-- real value heavy-->
      <xacro:box_inertial mass="${prop_weight}" x="${prop_diameter}" y="0.04" z="0.01"/>
    </link>
    <joint name="rotor_${number}_joint" type="continuous">
      <parent link="${parent}"/>
      <child link="rotor_${number}"/>
      <xacro:insert_block name="origin" />
      <axis xyz="0 0 1"/>
    </joint>
    <gazebo>
      <plugin filename="gz-sim-multicopter-motor-model-system" name="gz::sim::systems::MulticopterMotorModel">
        <jointName>rotor_${number}_joint</jointName>
        <linkName>rotor_${number}</linkName>
        <turningDirection>${direction}</turningDirection>
        <timeConstantUp>0.0125</timeConstantUp>
        <timeConstantDown>0.025</timeConstantDown>
        <maxRotVelocity>${prop_max_rad_per_sec}</maxRotVelocity>
        <motorConstant>4.25433673e-6</motorConstant> <!-- compute from: T/(rad sec)2 -->
        <momentConstant>0.016</momentConstant>
        <commandSubTopic>command/motor_speed</commandSubTopic>
        <actuator_number>${number}</actuator_number>
        <rotorDragCoefficient>8.06428e-05</rotorDragCoefficient>
        <rollingMomentCoefficient>1e-06</rollingMomentCoefficient>
        <rotorVelocitySlowdownSim>10</rotorVelocitySlowdownSim>
        <motorType>velocity</motorType>
      </plugin>
    </gazebo>
  </xacro:macro>

</robot>
